Auks API request failed : krb5 cred : unable to read credential cache
distributed.nanny - INFO - Closing Nanny at 'tcp://10.32.2.68:46441'
distributed.nanny - INFO - Closing Nanny at 'tcp://10.32.2.68:33193'
distributed.nanny - INFO - Closing Nanny at 'tcp://10.32.2.68:39119'
distributed.nanny - INFO - Closing Nanny at 'tcp://10.32.2.68:37985'
distributed.nanny - INFO - Closing Nanny at 'tcp://10.32.2.68:33701'
distributed.nanny - INFO - Closing Nanny at 'tcp://10.32.2.68:46281'
distributed.nanny - INFO - Closing Nanny at 'tcp://10.32.2.68:45963'
distributed.nanny - INFO - Closing Nanny at 'tcp://10.32.2.68:45887'
distributed.nanny - INFO - Closing Nanny at 'tcp://10.32.2.68:39645'
distributed.nanny - INFO - Closing Nanny at 'tcp://10.32.2.68:45525'
distributed.nanny - INFO - Closing Nanny at 'tcp://10.32.2.68:41259'
distributed.nanny - INFO - Closing Nanny at 'tcp://10.32.2.68:36161'
distributed.nanny - INFO - Closing Nanny at 'tcp://10.32.2.68:41129'
distributed.nanny - INFO - Closing Nanny at 'tcp://10.32.2.68:34563'
distributed.nanny - INFO - Closing Nanny at 'tcp://10.32.2.68:42245'
distributed.nanny - INFO - Closing Nanny at 'tcp://10.32.2.68:37735'
distributed.nanny - INFO - Closing Nanny at 'tcp://10.32.2.68:37703'
distributed.nanny - INFO - Closing Nanny at 'tcp://10.32.2.68:37661'
distributed.nanny - INFO - Closing Nanny at 'tcp://10.32.2.68:36527'
distributed.dask_worker - INFO - End worker
ConnectionRefusedError: [Errno 111] Connection refused

The above exception was the direct cause of the following exception:

Traceback (most recent call last):
  File "/hpcscratch/user/ikabadzh/mambaforge/envs/myenv/lib/python3.9/site-packages/distributed/comm/core.py", line 283, in connect
    comm = await asyncio.wait_for(
  File "/hpcscratch/user/ikabadzh/mambaforge/envs/myenv/lib/python3.9/asyncio/tasks.py", line 481, in wait_for
    return fut.result()
  File "/hpcscratch/user/ikabadzh/mambaforge/envs/myenv/lib/python3.9/site-packages/distributed/comm/tcp.py", line 403, in connect
    convert_stream_closed_error(self, e)
  File "/hpcscratch/user/ikabadzh/mambaforge/envs/myenv/lib/python3.9/site-packages/distributed/comm/tcp.py", line 126, in convert_stream_closed_error
    raise CommClosedError(f"in {obj}: {exc.__class__.__name__}: {exc}") from exc
distributed.comm.core.CommClosedError: in <distributed.comm.tcp.TCPConnector object at 0x7f8b1e519280>: ConnectionRefusedError: [Errno 111] Connection refused

The above exception was the direct cause of the following exception:

Traceback (most recent call last):
  File "/hpcscratch/user/ikabadzh/mambaforge/envs/myenv/lib/python3.9/site-packages/distributed/core.py", line 273, in _
    await asyncio.wait_for(self.start(), timeout=timeout)
  File "/hpcscratch/user/ikabadzh/mambaforge/envs/myenv/lib/python3.9/asyncio/tasks.py", line 481, in wait_for
    return fut.result()
  File "/hpcscratch/user/ikabadzh/mambaforge/envs/myenv/lib/python3.9/site-packages/distributed/nanny.py", line 330, in start
    msg = await self.scheduler.register_nanny()
  File "/hpcscratch/user/ikabadzh/mambaforge/envs/myenv/lib/python3.9/site-packages/distributed/core.py", line 871, in send_recv_from_rpc
    comm = await self.pool.connect(self.addr)
  File "/hpcscratch/user/ikabadzh/mambaforge/envs/myenv/lib/python3.9/site-packages/distributed/core.py", line 1059, in connect
    raise exc
  File "/hpcscratch/user/ikabadzh/mambaforge/envs/myenv/lib/python3.9/site-packages/distributed/core.py", line 1043, in connect
    comm = await fut
  File "/hpcscratch/user/ikabadzh/mambaforge/envs/myenv/lib/python3.9/site-packages/distributed/comm/core.py", line 307, in connect
    raise OSError(
OSError: Timed out trying to connect to tcp://188.185.68.194:36623 after 30 s

During handling of the above exception, another exception occurred:

Traceback (most recent call last):
  File "/hpcscratch/user/ikabadzh/mambaforge/envs/myenv/lib/python3.9/runpy.py", line 197, in _run_module_as_main
    return _run_code(code, main_globals, None,
  File "/hpcscratch/user/ikabadzh/mambaforge/envs/myenv/lib/python3.9/runpy.py", line 87, in _run_code
    exec(code, run_globals)
  File "/hpcscratch/user/ikabadzh/mambaforge/envs/myenv/lib/python3.9/site-packages/distributed/cli/dask_worker.py", line 469, in <module>
    go()
  File "/hpcscratch/user/ikabadzh/mambaforge/envs/myenv/lib/python3.9/site-packages/distributed/cli/dask_worker.py", line 465, in go
    main()
  File "/hpcscratch/user/ikabadzh/mambaforge/envs/myenv/lib/python3.9/site-packages/click/core.py", line 1128, in __call__
    return self.main(*args, **kwargs)
  File "/hpcscratch/user/ikabadzh/mambaforge/envs/myenv/lib/python3.9/site-packages/click/core.py", line 1053, in main
    rv = self.invoke(ctx)
  File "/hpcscratch/user/ikabadzh/mambaforge/envs/myenv/lib/python3.9/site-packages/click/core.py", line 1395, in invoke
    return ctx.invoke(self.callback, **ctx.params)
  File "/hpcscratch/user/ikabadzh/mambaforge/envs/myenv/lib/python3.9/site-packages/click/core.py", line 754, in invoke
    return __callback(*args, **kwargs)
  File "/hpcscratch/user/ikabadzh/mambaforge/envs/myenv/lib/python3.9/site-packages/distributed/cli/dask_worker.py", line 451, in main
    loop.run_sync(run)
  File "/hpcscratch/user/ikabadzh/mambaforge/envs/myenv/lib/python3.9/site-packages/tornado/ioloop.py", line 530, in run_sync
    return future_cell[0].result()
  File "/hpcscratch/user/ikabadzh/mambaforge/envs/myenv/lib/python3.9/site-packages/distributed/cli/dask_worker.py", line 445, in run
    await asyncio.gather(*nannies)
  File "/hpcscratch/user/ikabadzh/mambaforge/envs/myenv/lib/python3.9/asyncio/tasks.py", line 691, in _wrap_awaitable
    return (yield from awaitable.__await__())
  File "/hpcscratch/user/ikabadzh/mambaforge/envs/myenv/lib/python3.9/site-packages/distributed/core.py", line 277, in _
    raise TimeoutError(
asyncio.exceptions.TimeoutError: Nanny failed to start in 60 seconds
