Auks API request failed : krb5 cred : unable to read credential cache
distributed.nanny - INFO -         Start Nanny at: 'tcp://10.32.2.38:37447'
distributed.diskutils - INFO - Found stale lock file and directory '/tmp/ikabadzh/dask-worker-space/worker-_kt1117x', purging
distributed.worker - INFO -       Start worker at:     tcp://10.32.2.38:37181
distributed.worker - INFO -          Listening to:     tcp://10.32.2.38:37181
distributed.worker - INFO -          dashboard at:           10.32.2.38:45019
distributed.worker - INFO - Waiting to connect to: tcp://188.185.68.194:37826
distributed.worker - INFO - -------------------------------------------------
distributed.worker - INFO -               Threads:                          1
distributed.worker - INFO -                Memory:                  14.90 GiB
distributed.worker - INFO -       Local Directory: /tmp/ikabadzh/dask-worker-space/worker-boeq2i02
distributed.worker - INFO - -------------------------------------------------
distributed.nanny - INFO - Closing Nanny at 'tcp://10.32.2.38:45719'
distributed.nanny - INFO - Closing Nanny at 'tcp://10.32.2.38:42009'
distributed.nanny - INFO - Closing Nanny at 'tcp://10.32.2.38:45441'
distributed.nanny - INFO - Closing Nanny at 'tcp://10.32.2.38:35097'
distributed.nanny - INFO - Closing Nanny at 'tcp://10.32.2.38:35461'
distributed.nanny - INFO - Closing Nanny at 'tcp://10.32.2.38:44305'
distributed.nanny - INFO - Closing Nanny at 'tcp://10.32.2.38:43315'
distributed.nanny - INFO - Closing Nanny at 'tcp://10.32.2.38:45419'
distributed.nanny - INFO - Closing Nanny at 'tcp://10.32.2.38:39209'
distributed.nanny - INFO - Closing Nanny at 'tcp://10.32.2.38:44271'
distributed.nanny - INFO - Closing Nanny at 'tcp://10.32.2.38:40957'
distributed.nanny - INFO - Closing Nanny at 'tcp://10.32.2.38:42525'
distributed.nanny - INFO - Closing Nanny at 'tcp://10.32.2.38:32963'
distributed.nanny - INFO - Closing Nanny at 'tcp://10.32.2.38:39847'
distributed.nanny - INFO - Closing Nanny at 'tcp://10.32.2.38:45005'
distributed.nanny - INFO - Closing Nanny at 'tcp://10.32.2.38:41671'
distributed.nanny - INFO - Closing Nanny at 'tcp://10.32.2.38:34269'
distributed.nanny - INFO - Closing Nanny at 'tcp://10.32.2.38:44883'
distributed.nanny - INFO - Closing Nanny at 'tcp://10.32.2.38:39491'
distributed.nanny - INFO - Closing Nanny at 'tcp://10.32.2.38:40051'
distributed.nanny - INFO - Closing Nanny at 'tcp://10.32.2.38:39631'
distributed.nanny - INFO - Closing Nanny at 'tcp://10.32.2.38:35659'
distributed.nanny - INFO - Closing Nanny at 'tcp://10.32.2.38:37223'
distributed.nanny - INFO - Closing Nanny at 'tcp://10.32.2.38:42891'
distributed.nanny - INFO - Closing Nanny at 'tcp://10.32.2.38:43331'
distributed.nanny - INFO - Closing Nanny at 'tcp://10.32.2.38:33221'
distributed.nanny - INFO - Closing Nanny at 'tcp://10.32.2.38:33905'
distributed.nanny - INFO - Closing Nanny at 'tcp://10.32.2.38:34959'
distributed.nanny - INFO - Closing Nanny at 'tcp://10.32.2.38:41811'
distributed.nanny - INFO - Closing Nanny at 'tcp://10.32.2.38:39887'
distributed.nanny - INFO - Closing Nanny at 'tcp://10.32.2.38:41269'
distributed.dask_worker - INFO - End worker
Traceback (most recent call last):
  File "/hpcscratch/user/ikabadzh/mambaforge/envs/myenv/lib/python3.9/site-packages/distributed/comm/tcp.py", line 198, in read
    frames_nbytes = await stream.read_bytes(fmt_size)
asyncio.exceptions.CancelledError

During handling of the above exception, another exception occurred:

Traceback (most recent call last):
  File "/hpcscratch/user/ikabadzh/mambaforge/envs/myenv/lib/python3.9/asyncio/tasks.py", line 492, in wait_for
    fut.result()
asyncio.exceptions.CancelledError

The above exception was the direct cause of the following exception:

Traceback (most recent call last):
  File "/hpcscratch/user/ikabadzh/mambaforge/envs/myenv/lib/python3.9/site-packages/distributed/comm/core.py", line 318, in connect
    handshake = await asyncio.wait_for(comm.read(), time_left())
  File "/hpcscratch/user/ikabadzh/mambaforge/envs/myenv/lib/python3.9/asyncio/tasks.py", line 494, in wait_for
    raise exceptions.TimeoutError() from exc
asyncio.exceptions.TimeoutError

The above exception was the direct cause of the following exception:

Traceback (most recent call last):
  File "/hpcscratch/user/ikabadzh/mambaforge/envs/myenv/lib/python3.9/site-packages/distributed/core.py", line 273, in _
    await asyncio.wait_for(self.start(), timeout=timeout)
  File "/hpcscratch/user/ikabadzh/mambaforge/envs/myenv/lib/python3.9/asyncio/tasks.py", line 481, in wait_for
    return fut.result()
  File "/hpcscratch/user/ikabadzh/mambaforge/envs/myenv/lib/python3.9/site-packages/distributed/nanny.py", line 330, in start
    msg = await self.scheduler.register_nanny()
  File "/hpcscratch/user/ikabadzh/mambaforge/envs/myenv/lib/python3.9/site-packages/distributed/core.py", line 871, in send_recv_from_rpc
    comm = await self.pool.connect(self.addr)
  File "/hpcscratch/user/ikabadzh/mambaforge/envs/myenv/lib/python3.9/site-packages/distributed/core.py", line 1059, in connect
    raise exc
  File "/hpcscratch/user/ikabadzh/mambaforge/envs/myenv/lib/python3.9/site-packages/distributed/core.py", line 1043, in connect
    comm = await fut
  File "/hpcscratch/user/ikabadzh/mambaforge/envs/myenv/lib/python3.9/site-packages/distributed/comm/core.py", line 323, in connect
    raise OSError(
OSError: Timed out during handshake while connecting to tcp://188.185.68.194:37826 after 30 s

During handling of the above exception, another exception occurred:

Traceback (most recent call last):
  File "/hpcscratch/user/ikabadzh/mambaforge/envs/myenv/lib/python3.9/runpy.py", line 197, in _run_module_as_main
    return _run_code(code, main_globals, None,
  File "/hpcscratch/user/ikabadzh/mambaforge/envs/myenv/lib/python3.9/runpy.py", line 87, in _run_code
    exec(code, run_globals)
  File "/hpcscratch/user/ikabadzh/mambaforge/envs/myenv/lib/python3.9/site-packages/distributed/cli/dask_worker.py", line 469, in <module>
    go()
  File "/hpcscratch/user/ikabadzh/mambaforge/envs/myenv/lib/python3.9/site-packages/distributed/cli/dask_worker.py", line 465, in go
    main()
  File "/hpcscratch/user/ikabadzh/mambaforge/envs/myenv/lib/python3.9/site-packages/click/core.py", line 1128, in __call__
    return self.main(*args, **kwargs)
  File "/hpcscratch/user/ikabadzh/mambaforge/envs/myenv/lib/python3.9/site-packages/click/core.py", line 1053, in main
    rv = self.invoke(ctx)
  File "/hpcscratch/user/ikabadzh/mambaforge/envs/myenv/lib/python3.9/site-packages/click/core.py", line 1395, in invoke
    return ctx.invoke(self.callback, **ctx.params)
  File "/hpcscratch/user/ikabadzh/mambaforge/envs/myenv/lib/python3.9/site-packages/click/core.py", line 754, in invoke
    return __callback(*args, **kwargs)
  File "/hpcscratch/user/ikabadzh/mambaforge/envs/myenv/lib/python3.9/site-packages/distributed/cli/dask_worker.py", line 451, in main
    loop.run_sync(run)
  File "/hpcscratch/user/ikabadzh/mambaforge/envs/myenv/lib/python3.9/site-packages/tornado/ioloop.py", line 530, in run_sync
    return future_cell[0].result()
  File "/hpcscratch/user/ikabadzh/mambaforge/envs/myenv/lib/python3.9/site-packages/distributed/cli/dask_worker.py", line 445, in run
    await asyncio.gather(*nannies)
  File "/hpcscratch/user/ikabadzh/mambaforge/envs/myenv/lib/python3.9/asyncio/tasks.py", line 691, in _wrap_awaitable
    return (yield from awaitable.__await__())
  File "/hpcscratch/user/ikabadzh/mambaforge/envs/myenv/lib/python3.9/site-packages/distributed/core.py", line 277, in _
    raise TimeoutError(
asyncio.exceptions.TimeoutError: Nanny failed to start in 60 seconds
distributed.process - INFO - reaping stray process <SpawnProcess name='Dask Worker process (from Nanny)' pid=2991 parent=2954 started daemon>
Exception in thread AsyncProcess Dask Worker process (from Nanny) watch process join:
Traceback (most recent call last):
  File "/hpcscratch/user/ikabadzh/mambaforge/envs/myenv/lib/python3.9/threading.py", line 973, in _bootstrap_inner
